2019-11-05 09:48:56,895 INFO: Microblog startup [in C:\Users\Gilbert\Desktop\conges_mobilite\tutorials\microblog\app\__init__.py:48]
2019-11-05 09:49:07,431 ERROR: Exception on /edit_profile [POST] [in C:\Users\Gilbert\Anaconda3\envs\microblog_env\lib\site-packages\flask\app.py:1891]
Traceback (most recent call last):
  File "C:\Users\Gilbert\Anaconda3\envs\microblog_env\lib\site-packages\sqlalchemy\engine\base.py", line 1249, in _execute_context
    cursor, statement, parameters, context
  File "C:\Users\Gilbert\Anaconda3\envs\microblog_env\lib\site-packages\sqlalchemy\engine\default.py", line 580, in do_execute
    cursor.execute(statement, parameters)
sqlite3.IntegrityError: UNIQUE constraint failed: user.username

The above exception was the direct cause of the following exception:

Traceback (most recent call last):
  File "C:\Users\Gilbert\Anaconda3\envs\microblog_env\lib\site-packages\flask\app.py", line 2446, in wsgi_app
    response = self.full_dispatch_request()
  File "C:\Users\Gilbert\Anaconda3\envs\microblog_env\lib\site-packages\flask\app.py", line 1951, in full_dispatch_request
    rv = self.handle_user_exception(e)
  File "C:\Users\Gilbert\Anaconda3\envs\microblog_env\lib\site-packages\flask\app.py", line 1820, in handle_user_exception
    reraise(exc_type, exc_value, tb)
  File "C:\Users\Gilbert\Anaconda3\envs\microblog_env\lib\site-packages\flask\_compat.py", line 39, in reraise
    raise value
  File "C:\Users\Gilbert\Anaconda3\envs\microblog_env\lib\site-packages\flask\app.py", line 1949, in full_dispatch_request
    rv = self.dispatch_request()
  File "C:\Users\Gilbert\Anaconda3\envs\microblog_env\lib\site-packages\flask\app.py", line 1935, in dispatch_request
    return self.view_functions[rule.endpoint](**req.view_args)
  File "C:\Users\Gilbert\Anaconda3\envs\microblog_env\lib\site-packages\flask_login\utils.py", line 261, in decorated_view
    return func(*args, **kwargs)
  File "C:\Users\Gilbert\Desktop\conges_mobilite\tutorials\microblog\app\routes.py", line 91, in edit_profile
    db.session.commit()
  File "C:\Users\Gilbert\Anaconda3\envs\microblog_env\lib\site-packages\sqlalchemy\orm\scoping.py", line 162, in do
    return getattr(self.registry(), name)(*args, **kwargs)
  File "C:\Users\Gilbert\Anaconda3\envs\microblog_env\lib\site-packages\sqlalchemy\orm\session.py", line 1027, in commit
    self.transaction.commit()
  File "C:\Users\Gilbert\Anaconda3\envs\microblog_env\lib\site-packages\sqlalchemy\orm\session.py", line 494, in commit
    self._prepare_impl()
  File "C:\Users\Gilbert\Anaconda3\envs\microblog_env\lib\site-packages\sqlalchemy\orm\session.py", line 473, in _prepare_impl
    self.session.flush()
  File "C:\Users\Gilbert\Anaconda3\envs\microblog_env\lib\site-packages\sqlalchemy\orm\session.py", line 2470, in flush
    self._flush(objects)
  File "C:\Users\Gilbert\Anaconda3\envs\microblog_env\lib\site-packages\sqlalchemy\orm\session.py", line 2608, in _flush
    transaction.rollback(_capture_exception=True)
  File "C:\Users\Gilbert\Anaconda3\envs\microblog_env\lib\site-packages\sqlalchemy\util\langhelpers.py", line 68, in __exit__
    compat.reraise(exc_type, exc_value, exc_tb)
  File "C:\Users\Gilbert\Anaconda3\envs\microblog_env\lib\site-packages\sqlalchemy\util\compat.py", line 153, in reraise
    raise value
  File "C:\Users\Gilbert\Anaconda3\envs\microblog_env\lib\site-packages\sqlalchemy\orm\session.py", line 2568, in _flush
    flush_context.execute()
  File "C:\Users\Gilbert\Anaconda3\envs\microblog_env\lib\site-packages\sqlalchemy\orm\unitofwork.py", line 422, in execute
    rec.execute(self)
  File "C:\Users\Gilbert\Anaconda3\envs\microblog_env\lib\site-packages\sqlalchemy\orm\unitofwork.py", line 589, in execute
    uow,
  File "C:\Users\Gilbert\Anaconda3\envs\microblog_env\lib\site-packages\sqlalchemy\orm\persistence.py", line 236, in save_obj
    update,
  File "C:\Users\Gilbert\Anaconda3\envs\microblog_env\lib\site-packages\sqlalchemy\orm\persistence.py", line 996, in _emit_update_statements
    statement, multiparams
  File "C:\Users\Gilbert\Anaconda3\envs\microblog_env\lib\site-packages\sqlalchemy\engine\base.py", line 988, in execute
    return meth(self, multiparams, params)
  File "C:\Users\Gilbert\Anaconda3\envs\microblog_env\lib\site-packages\sqlalchemy\sql\elements.py", line 287, in _execute_on_connection
    return connection._execute_clauseelement(self, multiparams, params)
  File "C:\Users\Gilbert\Anaconda3\envs\microblog_env\lib\site-packages\sqlalchemy\engine\base.py", line 1107, in _execute_clauseelement
    distilled_params,
  File "C:\Users\Gilbert\Anaconda3\envs\microblog_env\lib\site-packages\sqlalchemy\engine\base.py", line 1253, in _execute_context
    e, statement, parameters, cursor, context
  File "C:\Users\Gilbert\Anaconda3\envs\microblog_env\lib\site-packages\sqlalchemy\engine\base.py", line 1473, in _handle_dbapi_exception
    util.raise_from_cause(sqlalchemy_exception, exc_info)
  File "C:\Users\Gilbert\Anaconda3\envs\microblog_env\lib\site-packages\sqlalchemy\util\compat.py", line 398, in raise_from_cause
    reraise(type(exception), exception, tb=exc_tb, cause=cause)
  File "C:\Users\Gilbert\Anaconda3\envs\microblog_env\lib\site-packages\sqlalchemy\util\compat.py", line 152, in reraise
    raise value.with_traceback(tb)
  File "C:\Users\Gilbert\Anaconda3\envs\microblog_env\lib\site-packages\sqlalchemy\engine\base.py", line 1249, in _execute_context
    cursor, statement, parameters, context
  File "C:\Users\Gilbert\Anaconda3\envs\microblog_env\lib\site-packages\sqlalchemy\engine\default.py", line 580, in do_execute
    cursor.execute(statement, parameters)
sqlalchemy.exc.IntegrityError: (sqlite3.IntegrityError) UNIQUE constraint failed: user.username
[SQL: UPDATE user SET username=?, about_me=? WHERE user.id = ?]
[parameters: ('Elonga', '', 3)]
(Background on this error at: http://sqlalche.me/e/gkpj)
2019-11-05 10:09:59,319 INFO: Microblog startup [in C:\Users\Gilbert\Desktop\conges_mobilite\tutorials\microblog\app\__init__.py:48]
2019-11-05 10:10:27,553 INFO: Microblog startup [in C:\Users\Gilbert\Desktop\conges_mobilite\tutorials\microblog\app\__init__.py:48]
2019-11-05 10:10:38,356 INFO: Microblog startup [in C:\Users\Gilbert\Desktop\conges_mobilite\tutorials\microblog\app\__init__.py:48]
2019-11-05 10:30:50,520 INFO: Microblog startup [in C:\Users\Gilbert\Desktop\conges_mobilite\tutorials\microblog\app\__init__.py:48]
2019-11-05 10:33:38,949 INFO: Microblog startup [in C:\Users\Gilbert\Desktop\conges_mobilite\tutorials\microblog\app\__init__.py:48]
2019-11-05 14:45:30,853 INFO: Microblog startup [in C:\Users\Gilbert\Desktop\conges_mobilite\tutorials\microblog\app\__init__.py:48]
2019-11-05 15:02:09,465 INFO: Microblog startup [in C:\Users\Gilbert\Desktop\conges_mobilite\tutorials\microblog\app\__init__.py:48]
2019-11-05 15:02:11,475 ERROR: Exception on /index [GET] [in C:\Users\Gilbert\Anaconda3\envs\microblog_env\lib\site-packages\flask\app.py:1891]
Traceback (most recent call last):
  File "C:\Users\Gilbert\Anaconda3\envs\microblog_env\lib\site-packages\flask\app.py", line 2446, in wsgi_app
    response = self.full_dispatch_request()
  File "C:\Users\Gilbert\Anaconda3\envs\microblog_env\lib\site-packages\flask\app.py", line 1951, in full_dispatch_request
    rv = self.handle_user_exception(e)
  File "C:\Users\Gilbert\Anaconda3\envs\microblog_env\lib\site-packages\flask\app.py", line 1820, in handle_user_exception
    reraise(exc_type, exc_value, tb)
  File "C:\Users\Gilbert\Anaconda3\envs\microblog_env\lib\site-packages\flask\_compat.py", line 39, in reraise
    raise value
  File "C:\Users\Gilbert\Anaconda3\envs\microblog_env\lib\site-packages\flask\app.py", line 1949, in full_dispatch_request
    rv = self.dispatch_request()
  File "C:\Users\Gilbert\Anaconda3\envs\microblog_env\lib\site-packages\flask\app.py", line 1935, in dispatch_request
    return self.view_functions[rule.endpoint](**req.view_args)
  File "C:\Users\Gilbert\Anaconda3\envs\microblog_env\lib\site-packages\flask_login\utils.py", line 261, in decorated_view
    return func(*args, **kwargs)
  File "C:\Users\Gilbert\Desktop\conges_mobilite\tutorials\microblog\app\routes.py", line 131, in index
    page, app.config['POSTS_PER_PAGE'], False)
NameError: name 'page' is not defined
2019-11-05 15:02:14,624 ERROR: Exception on /index [GET] [in C:\Users\Gilbert\Anaconda3\envs\microblog_env\lib\site-packages\flask\app.py:1891]
Traceback (most recent call last):
  File "C:\Users\Gilbert\Anaconda3\envs\microblog_env\lib\site-packages\flask\app.py", line 2446, in wsgi_app
    response = self.full_dispatch_request()
  File "C:\Users\Gilbert\Anaconda3\envs\microblog_env\lib\site-packages\flask\app.py", line 1951, in full_dispatch_request
    rv = self.handle_user_exception(e)
  File "C:\Users\Gilbert\Anaconda3\envs\microblog_env\lib\site-packages\flask\app.py", line 1820, in handle_user_exception
    reraise(exc_type, exc_value, tb)
  File "C:\Users\Gilbert\Anaconda3\envs\microblog_env\lib\site-packages\flask\_compat.py", line 39, in reraise
    raise value
  File "C:\Users\Gilbert\Anaconda3\envs\microblog_env\lib\site-packages\flask\app.py", line 1949, in full_dispatch_request
    rv = self.dispatch_request()
  File "C:\Users\Gilbert\Anaconda3\envs\microblog_env\lib\site-packages\flask\app.py", line 1935, in dispatch_request
    return self.view_functions[rule.endpoint](**req.view_args)
  File "C:\Users\Gilbert\Anaconda3\envs\microblog_env\lib\site-packages\flask_login\utils.py", line 261, in decorated_view
    return func(*args, **kwargs)
  File "C:\Users\Gilbert\Desktop\conges_mobilite\tutorials\microblog\app\routes.py", line 131, in index
    page, app.config['POSTS_PER_PAGE'], False)
NameError: name 'page' is not defined
